Workbook

Sheet 2300z
E7: WIND | L7: TEMP AND HUMIDITY | Q7: CLOUDS | U7: CLOUDS REPORTED BY 8NsChshs GROUPS | AH7: REMARKS | AN7: S.rule - Formula | AY7: Formula
A8: DAY | B8: HOUR | C8: Total cloud Amt. | D8: Wind indicator | E8: DIRECTION | F8: SPEED | G8: VISIBILITY | H8: Weather Indicator | I8: PRESENT WEATHER | J8: PAST WEATHER | K8: SEA LEVEL PRESSURE | L8: Dry Bulb | M8: Wet Bulb | N8: Vapour Pressure | O8: Relative humidity | P8: Dew Point | Q8: Total amt. Nh | R8: Form of CL | S8: Form of CM | T8: Form of CH | U8: Lowest layer | X8: 3/8 or more | AB8: 5/8 or more | AE8: Cb cloud | AN8: Vapour Pressure | AO8: Relative humidity | AP8: Dew Point | AY8: Vapour Pressure | AZ8: Relative humidity | BA8: Dew Point
U9: Amount | V9: Form | W9: Height | X9: Indicator | Y9: Amount | Z9: Form | AA9: Height | AB9: Amount | AC9: Form | AD9: Height | AE9: Amount | AF9: Form | AG9: Height | BC9: ####### | BD9: ********* | BE9: &&&&&&
A10: 1 | B10: 19 | C10: 7 | D10: 4 | E10: 9 | F10: 11 | G10: 76 | H10: 2 | K10: 125 | L10: 271 | M10: 248 | N10: 295 | O10: 82 | P10: 238 | Q10: 1 | R10: 2 | S10: 0 | T10: 2 | U10: 1 | V10: 8 | W10: 63 | X10: 8 | Y10: 7 | Z10: 0 | AA10: 840 | AN10: =N10-AY10 -> -2.1098097 | AO10: =O10-AZ10 -> -0.84773036 | AP10: =P10-BA10 -> -1.3211153 | AY10: =10*(BE10-BD10*((L10/10)-(M10/10))*0.00066*(1+(0.00115*(M10/10)))) -> 297.10981 | AZ10: =((AY10/10)*100)/BC10 -> 82.84773 | BA10: =(243.5*LN((AY10/10)/6.112))/(17.67-LN((AY10/10)/6.112))*10 -> 239.32112 | BC10: =6.112*2.718^((17.67*(L10/10))/((L10/10)+243.5)) -> 35.862154 | BD10: 1013.2 | BE10: =6.112*2.718^((17.67*(M10/10))/((M10/10)+243.5)) -> 31.292883
A11: 2 | B11: 19 | C11: 4 | D11: 4 | E11: 8 | F11: 9 | G11: 75 | H11: 2 | K11: 119 | L11: 269 | M11: 246 | N11: 292 | O11: 82 | P11: 236 | Q11: 1 | R11: 2 | S11: 0 | T11: 1 | U11: 1 | V11: 8 | W11: 60 | X11: 8 | Y11: 3 | Z11: 0 | AA11: 840 | AN11: =N11-AY11 -> -1.3923988 | AO11: =O11-AZ11 -> -0.77887776 | AP11: =P11-BA11 -> -1.2298621 | AY11: =10*(BE11-BD11*((L11/10)-(M11/10))*0.00066*(1+(0.00115*(M11/10)))) -> 293.3924 | AZ11: =((AY11/10)*100)/BC11 -> 82.778878 | BA11: =(243.5*LN((AY11/10)/6.112))/(17.67-LN((AY11/10)/6.112))*10 -> 237.22986 | BC11: =6.112*2.718^((17.67*(L11/10))/((L11/10)+243.5)) -> 35.442906 | BD11: 1013.2 | BE11: =6.112*2.718^((17.67*(M11/10))/((M11/10)+243.5)) -> 30.920789
A12: 3 | B12: 19 | C12: 2 | D12: 4 | E12: 7 | F12: 10 | G12: 75 | H12: 2 | K12: 124 | L12: 271 | M12: 242 | N12: 279 | O12: 78 | P12: 229 | Q12: 1 | R12: 2 | S12: 0 | T12: 2 | U12: 1 | V12: 8 | W12: 63 | X12: 8 | AN12: =N12-AY12 -> -2.9496638 | AO12: =O12-AZ12 -> -0.62039203 | AP12: =P12-BA12 -> -1.6437156 | AY12: =10*(BE12-BD12*((L12/10)-(M12/10))*0.00066*(1+(0.00115*(M12/10)))) -> 281.94966 | AZ12: =((AY12/10)*100)/BC12 -> 78.620392 | BA12: =(243.5*LN((AY12/10)/6.112))/(17.67-LN((AY12/10)/6.112))*10 -> 230.64372 | BC12: =6.112*2.718^((17.67*(L12/10))/((L12/10)+243.5)) -> 35.862154 | BD12: 1013.2 | BE12: =6.112*2.718^((17.67*(M12/10))/((M12/10)+243.5)) -> 30.188201
A13: 4 | B13: 19 | C13: 1 | D13: 4 | E13: 9 | F13: 13 | G13: 80 | H13: 2 | K13: 127 | L13: 271 | M13: 247 | N13: 291 | O13: 81 | P13: 236 | Q13: 1 | R13: 2 | S13: 0 | T13: 2 | U13: 1 | V13: 8 | W13: 66 | X13: 8 | AN13: =N13-AY13 -> -3.5585275 | AO13: =O13-AZ13 -> -1.1363168 | AP13: =P13-BA13 -> -1.888361 | AY13: =10*(BE13-BD13*((L13/10)-(M13/10))*0.00066*(1+(0.00115*(M13/10)))) -> 294.55853 | AZ13: =((AY13/10)*100)/BC13 -> 82.136317 | BA13: =(243.5*LN((AY13/10)/6.112))/(17.67-LN((AY13/10)/6.112))*10 -> 237.88836 | BC13: =6.112*2.718^((17.67*(L13/10))/((L13/10)+243.5)) -> 35.862154 | BD13: 1013.2 | BE13: =6.112*2.718^((17.67*(M13/10))/((M13/10)+243.5)) -> 31.106349
A14: 5 | B14: 19 | C14: 6 | D14: 4 | E14: 10 | F14: 13 | G14: 78 | H14: 2 | K14: 122 | L14: 270 | M14: 246 | N14: 290 | O14: 81 | P14: 235 | Q14: 1 | R14: 1 | S14: 0 | T14: 1 | U14: 1 | V14: 8 | W14: 60 | X14: 8 | Y14: 5 | Z14: 0 | AA14: 900 | AN14: =N14-AY14 -> -2.7047689 | AO14: =O14-AZ14 -> -1.1005383 | AP14: =P14-BA14 -> -1.8404906 | AY14: =10*(BE14-BD14*((L14/10)-(M14/10))*0.00066*(1+(0.00115*(M14/10)))) -> 292.70477 | AZ14: =((AY14/10)*100)/BC14 -> 82.100538 | BA14: =(243.5*LN((AY14/10)/6.112))/(17.67-LN((AY14/10)/6.112))*10 -> 236.84049 | BC14: =6.112*2.718^((17.67*(L14/10))/((L14/10)+243.5)) -> 35.651991 | BD14: 1013.2 | BE14: =6.112*2.718^((17.67*(M14/10))/((M14/10)+243.5)) -> 30.920789
A15: 6 | B15: 19 | C15: 2 | D15: 4 | E15: 9 | F15: 12 | G15: 80 | H15: 2 | K15: 117 | L15: 270 | M15: 246 | N15: 291 | O15: 81 | P15: 236 | Q15: 1 | R15: 1 | S15: 0 | T15: 1 | U15: 1 | V15: 8 | W15: 66 | X15: 8 | AN15: =N15-AY15 -> -1.7047689 | AO15: =O15-AZ15 -> -1.1005383 | AP15: =P15-BA15 -> -0.8404906 | AY15: =10*(BE15-BD15*((L15/10)-(M15/10))*0.00066*(1+(0.00115*(M15/10)))) -> 292.70477 | AZ15: =((AY15/10)*100)/BC15 -> 82.100538 | BA15: =(243.5*LN((AY15/10)/6.112))/(17.67-LN((AY15/10)/6.112))*10 -> 236.84049 | BC15: =6.112*2.718^((17.67*(L15/10))/((L15/10)+243.5)) -> 35.651991 | BD15: 1013.2 | BE15: =6.112*2.718^((17.67*(M15/10))/((M15/10)+243.5)) -> 30.920789
A16: 7 | B16: 19 | C16: 4 | D16: 4 | E16: 9 | F16: 11 | G16: 76 | H16: 2 | K16: 108 | L16: 269 | M16: 238 | N16: 270 | O16: 76 | P16: 223 | Q16: 1 | R16: 2 | S16: 0 | T16: 2 | U16: 1 | V16: 8 | W16: 69 | X16: 8 | Y16: 4 | Z16: 0 | AA16: 840 | AN16: =N16-AY16 -> -3.4110965 | AO16: =O16-AZ16 -> -1.1412751 | AP16: =P16-BA16 -> -2.574788 | AY16: =10*(BE16-BD16*((L16/10)-(M16/10))*0.00066*(1+(0.00115*(M16/10)))) -> 273.4111 | AZ16: =((AY16/10)*100)/BC16 -> 77.141275 | BA16: =(243.5*LN((AY16/10)/6.112))/(17.67-LN((AY16/10)/6.112))*10 -> 225.57479 | BC16: =6.112*2.718^((17.67*(L16/10))/((L16/10)+243.5)) -> 35.442906 | BD16: 1013.2 | BE16: =6.112*2.718^((17.67*(M16/10))/((M16/10)+243.5)) -> 29.470855
A17: 8 | B17: 19 | C17: 1 | D17: 4 | E17: 10 | F17: 14 | G17: 75 | H17: 2 | K17: 116 | L17: 273 | M17: 250 | N17: 299 | O17: 82 | P17: 240 | Q17: 1 | R17: 8 | S17: 0 | T17: 0 | U17: 1 | V17: 8 | W17: 63 | X17: 8 | AH17: hz | AN17: =N17-AY17 -> -1.8663543 | AO17: =O17-AZ17 -> -0.91588468 | AP17: =P17-BA17 -> -1.4112355 | AY17: =10*(BE17-BD17*((L17/10)-(M17/10))*0.00066*(1+(0.00115*(M17/10)))) -> 300.86635 | AZ17: =((AY17/10)*100)/BC17 -> 82.915885 | BA17: =(243.5*LN((AY17/10)/6.112))/(17.67-LN((AY17/10)/6.112))*10 -> 241.41124 | BC17: =6.112*2.718^((17.67*(L17/10))/((L17/10)+243.5)) -> 36.285732 | BD17: 1013.2 | BE17: =6.112*2.718^((17.67*(M17/10))/((M17/10)+243.5)) -> 31.668892
A18: 9 | B18: 19 | C18: 5 | D18: 4 | E18: 9 | F18: 12 | G18: 78 | H18: 2 | K18: 115 | L18: 270 | M18: 246 | N18: 291 | O18: 82 | P18: 236 | Q18: 1 | R18: 2 | S18: 0 | T18: 1 | U18: 1 | V18: 8 | W18: 66 | X18: 8 | Y18: 5 | Z18: 0 | AA18: 900 | AN18: =N18-AY18 -> -1.7047689 | AO18: =O18-AZ18 -> -0.10053827 | AP18: =P18-BA18 -> -0.8404906 | AY18: =10*(BE18-BD18*((L18/10)-(M18/10))*0.00066*(1+(0.00115*(M18/10)))) -> 292.70477 | AZ18: =((AY18/10)*100)/BC18 -> 82.100538 | BA18: =(243.5*LN((AY18/10)/6.112))/(17.67-LN((AY18/10)/6.112))*10 -> 236.84049 | BC18: =6.112*2.718^((17.67*(L18/10))/((L18/10)+243.5)) -> 35.651991 | BD18: 1013.2 | BE18: =6.112*2.718^((17.67*(M18/10))/((M18/10)+243.5)) -> 30.920789
A19: 10 | B19: 19 | C19: 4 | D19: 4 | E19: 8 | F19: 12 | G19: 75 | H19: 2 | K19: 91 | L19: 275 | M19: 250 | N19: 297 | O19: 80 | P19: 239 | Q19: 1 | R19: 2 | S19: 0 | T19: 1 | U19: 1 | V19: 8 | W19: 66 | X19: 8 | Y19: 4 | Z19: 0 | AA19: 900 | AN19: =N19-AY19 -> -2.4904793 | AO19: =O19-AZ19 -> -1.5746379 | AP19: =P19-BA19 -> -1.6483724 | AY19: =10*(BE19-BD19*((L19/10)-(M19/10))*0.00066*(1+(0.00115*(M19/10)))) -> 299.49048 | AZ19: =((AY19/10)*100)/BC19 -> 81.574638 | BA19: =(243.5*LN((AY19/10)/6.112))/(17.67-LN((AY19/10)/6.112))*10 -> 240.64837 | BC19: =6.112*2.718^((17.67*(L19/10))/((L19/10)+243.5)) -> 36.713676 | BD19: 1013.2 | BE19: =6.112*2.718^((17.67*(M19/10))/((M19/10)+243.5)) -> 31.668892
A20: 11 | B20: 19 | C20: 6 | D20: 4 | E20: 0 | F20: 0 | G20: 70 | H20: 1 | I20: 5 | J20: 22 | K20: 100 | L20: 269 | M20: 240 | N20: 276 | O20: 78 | P20: 227 | Q20: 2 | R20: 8 | S20: 0 | T20: 2 | U20: 2 | V20: 8 | W20: 54 | X20: 8 | Y20: 6 | Z20: 0 | AA20: 840 | AH20: hz | AN20: =N20-AY20 -> -2.3485121 | AO20: =O20-AZ20 -> -0.53433678 | AP20: =P20-BA20 -> -1.522518 | AY20: =10*(BE20-BD20*((L20/10)-(M20/10))*0.00066*(1+(0.00115*(M20/10)))) -> 278.34851 | AZ20: =((AY20/10)*100)/BC20 -> 78.534337 | BA20: =(243.5*LN((AY20/10)/6.112))/(17.67-LN((AY20/10)/6.112))*10 -> 228.52252 | BC20: =6.112*2.718^((17.67*(L20/10))/((L20/10)+243.5)) -> 35.442906 | BD20: 1013.2 | BE20: =6.112*2.718^((17.67*(M20/10))/((M20/10)+243.5)) -> 29.82764
A21: 12 | B21: 19 | C21: 7 | D21: 4 | E21: 8 | F21: 5 | G21: 75 | H21: 2 | K21: 116 | L21: 265 | M21: 233 | N21: 262 | O21: 76 | P21: 218 | Q21: 2 | R21: 8 | S21: 4 | T21: 2 | U21: 1 | V21: 8 | W21: 63 | X21: 8 | Y21: 7 | Z21: 0 | AA21: 840 | AN21: =N21-AY21 -> -1.979795 | AO21: =O21-AZ21 -> -0.25672794 | AP21: =P21-BA21 -> -1.8120397 | AY21: =10*(BE21-BD21*((L21/10)-(M21/10))*0.00066*(1+(0.00115*(M21/10)))) -> 263.9798 | AZ21: =((AY21/10)*100)/BC21 -> 76.256728 | BA21: =(243.5*LN((AY21/10)/6.112))/(17.67-LN((AY21/10)/6.112))*10 -> 219.81204 | BC21: =6.112*2.718^((17.67*(L21/10))/((L21/10)+243.5)) -> 34.617247 | BD21: 1013.2 | BE21: =6.112*2.718^((17.67*(M21/10))/((M21/10)+243.5)) -> 28.595196
A22: 13 | B22: 19 | C22: 1 | D22: 4 | E22: 7 | F22: 10 | G22: 78 | H22: 2 | K22: 125 | L22: 269 | M22: 240 | N22: 277 | O22: 78 | P22: 227 | Q22: 1 | R22: 2 | S22: 0 | T22: 1 | U22: 1 | V22: 8 | W22: 57 | X22: 8 | AN22: =N22-AY22 -> -1.3485121 | AO22: =O22-AZ22 -> -0.53433678 | AP22: =P22-BA22 -> -1.522518 | AY22: =10*(BE22-BD22*((L22/10)-(M22/10))*0.00066*(1+(0.00115*(M22/10)))) -> 278.34851 | AZ22: =((AY22/10)*100)/BC22 -> 78.534337 | BA22: =(243.5*LN((AY22/10)/6.112))/(17.67-LN((AY22/10)/6.112))*10 -> 228.52252 | BC22: =6.112*2.718^((17.67*(L22/10))/((L22/10)+243.5)) -> 35.442906 | BD22: 1013.2 | BE22: =6.112*2.718^((17.67*(M22/10))/((M22/10)+243.5)) -> 29.82764
A23: 14 | B23: 19 | C23: 6 | D23: 4 | E23: 6 | F23: 10 | G23: 76 | H23: 2 | K23: 118 | L23: 265 | M23: 236 | N23: 268 | O23: 77 | P23: 222 | Q23: 1 | R23: 8 | S23: 6 | T23: 1 | U23: 1 | V23: 8 | W23: 60 | X23: 8 | Y23: 5 | Z23: 0 | AA23: 840 | AN23: =N23-AY23 -> -3.2591691 | AO23: =O23-AZ23 -> -1.3595451 | AP23: =P23-BA23 -> -2.2754281 | AY23: =10*(BE23-BD23*((L23/10)-(M23/10))*0.00066*(1+(0.00115*(M23/10)))) -> 271.25917 | AZ23: =((AY23/10)*100)/BC23 -> 78.359545 | BA23: =(243.5*LN((AY23/10)/6.112))/(17.67-LN((AY23/10)/6.112))*10 -> 224.27543 | BC23: =6.112*2.718^((17.67*(L23/10))/((L23/10)+243.5)) -> 34.617247 | BD23: 1013.2 | BE23: =6.112*2.718^((17.67*(M23/10))/((M23/10)+243.5)) -> 29.117813
A24: 15 | B24: 19 | C24: 2 | D24: 4 | E24: 7 | F24: 8 | G24: 78 | H24: 2 | K24: 112 | L24: 269 | M24: 235 | N24: 261 | O24: 73 | P24: 218 | Q24: 1 | R24: 1 | S24: 0 | T24: 1 | U24: 1 | V24: 8 | W24: 63 | X24: 8 | AH24: hz | AN24: =N24-AY24 -> -5.0762028 | AO24: =O24-AZ24 -> -2.0717795 | AP24: =P24-BA24 -> -3.1084138 | AY24: =10*(BE24-BD24*((L24/10)-(M24/10))*0.00066*(1+(0.00115*(M24/10)))) -> 266.0762 | AZ24: =((AY24/10)*100)/BC24 -> 75.071779 | BA24: =(243.5*LN((AY24/10)/6.112))/(17.67-LN((AY24/10)/6.112))*10 -> 221.10841 | BC24: =6.112*2.718^((17.67*(L24/10))/((L24/10)+243.5)) -> 35.442906 | BD24: 1013.2 | BE24: =6.112*2.718^((17.67*(M24/10))/((M24/10)+243.5)) -> 28.942686
A25: 16 | B25: 19 | C25: 6 | D25: 4 | E25: 10 | F25: 10 | G25: 68 | H25: 1 | I25: 15 | J25: 22 | K25: 128 | L25: 264 | M25: 238 | N25: 274 | O25: 80 | P25: 226 | Q25: 4 | R25: 8 | S25: 0 | T25: 2 | U25: 2 | V25: 8 | W25: 54 | X25: 8 | Y25: 5 | Z25: 0 | AA25: 840 | AH25: jp-ene | AN25: =N25-AY25 -> -2.8461698 | AO25: =O25-AZ25 -> -0.44701611 | AP25: =P25-BA25 -> -1.6304737 | AY25: =10*(BE25-BD25*((L25/10)-(M25/10))*0.00066*(1+(0.00115*(M25/10)))) -> 276.84617 | AZ25: =((AY25/10)*100)/BC25 -> 80.447016 | BA25: =(243.5*LN((AY25/10)/6.112))/(17.67-LN((AY25/10)/6.112))*10 -> 227.63047 | BC25: =6.112*2.718^((17.67*(L25/10))/((L25/10)+243.5)) -> 34.413479 | BD25: 1013.2 | BE25: =6.112*2.718^((17.67*(M25/10))/((M25/10)+243.5)) -> 29.470855
A26: 17 | B26: 19 | C26: 8 | D26: 4 | E26: 0 | F26: 0 | G26: 70 | H26: 1 | I26: 5 | J26: 22 | K26: 140 | L26: 241 | M26: 235 | N26: 284 | O26: 95 | P26: 232 | Q26: 6 | R26: 8 | S26: 4 | T26: 2 | U26: 2 | V26: 8 | W26: 45 | X26: 8 | Y26: 6 | Z26: 6 | AA26: 105 | AH26: hz | AN26: =N26-AY26 -> -1.3061532 | AO26: =O26-AZ26 -> -0.078452147 | AP26: =P26-BA26 -> -0.59953439 | AY26: =10*(BE26-BD26*((L26/10)-(M26/10))*0.00066*(1+(0.00115*(M26/10)))) -> 285.30615 | AZ26: =((AY26/10)*100)/BC26 -> 95.078452 | BA26: =(243.5*LN((AY26/10)/6.112))/(17.67-LN((AY26/10)/6.112))*10 -> 232.59953 | BC26: =6.112*2.718^((17.67*(L26/10))/((L26/10)+243.5)) -> 30.007446 | BD26: 1013.2 | BE26: =6.112*2.718^((17.67*(M26/10))/((M26/10)+243.5)) -> 28.942686
A27: 18 | B27: 19 | C27: 6 | D27: 4 | E27: 9 | F27: 8 | G27: 68 | H27: 1 | I27: 80 | J27: 22 | K27: 137 | L27: 270 | M27: 250 | N27: 300 | O27: 84 | P27: 241 | Q27: 5 | R27: 8 | S27: 0 | T27: 2 | U27: 4 | V27: 8 | W27: 54 | X27: 8 | AH27: pro @ 18:52-57 | AN27: =N27-AY27 -> -2.9301667 | AO27: =O27-AZ27 -> -0.96865233 | AP27: =P27-BA27 -> -1.5498225 | AY27: =10*(BE27-BD27*((L27/10)-(M27/10))*0.00066*(1+(0.00115*(M27/10)))) -> 302.93017 | AZ27: =((AY27/10)*100)/BC27 -> 84.968652 | BA27: =(243.5*LN((AY27/10)/6.112))/(17.67-LN((AY27/10)/6.112))*10 -> 242.54982 | BC27: =6.112*2.718^((17.67*(L27/10))/((L27/10)+243.5)) -> 35.651991 | BD27: 1013.2 | BE27: =6.112*2.718^((17.67*(M27/10))/((M27/10)+243.5)) -> 31.668892
A28: 19 | B28: 19 | C28: 5 | D28: 4 | E28: 9 | F28: 14 | G28: 72 | H28: 1 | I28: 5 | J28: 11 | K28: 117 | L28: 274 | M28: 247 | N28: 290 | O28: 79 | P28: 235 | Q28: 4 | R28: 8 | S28: 3 | T28: 1 | U28: 1 | V28: 8 | W28: 57 | X28: 8 | Y28: 4 | Z28: 6 | AA28: 114 | AH28: hz | AN28: =N28-AY28 -> -2.4954072 | AO28: =O28-AZ28 -> -1.1375823 | AP28: =P28-BA28 -> -1.7217801 | AY28: =10*(BE28-BD28*((L28/10)-(M28/10))*0.00066*(1+(0.00115*(M28/10)))) -> 292.49541 | AZ28: =((AY28/10)*100)/BC28 -> 80.137582 | BA28: =(243.5*LN((AY28/10)/6.112))/(17.67-LN((AY28/10)/6.112))*10 -> 236.72178 | BC28: =6.112*2.718^((17.67*(L28/10))/((L28/10)+243.5)) -> 36.499155 | BD28: 1013.2 | BE28: =6.112*2.718^((17.67*(M28/10))/((M28/10)+243.5)) -> 31.106349
A29: 20 | B29: 19 | C29: 7 | D29: 4 | E29: 9 | F29: 13 | G29: 65 | H29: 1 | I29: 5 | J29: 22 | K29: 115 | L29: 260 | M29: 246 | N29: 298 | O29: 89 | P29: 240 | Q29: 6 | R29: 8 | S29: 3 | T29: 2 | U29: 5 | V29: 8 | W29: 51 | X29: 8 | Y29: 7 | Z29: 0 | AA29: 840 | AH29: hz | AN29: =N29-AY29 -> -1.5810675 | AO29: =O29-AZ29 -> -0.1375266 | AP29: =P29-BA29 -> -0.69869392 | AY29: =10*(BE29-BD29*((L29/10)-(M29/10))*0.00066*(1+(0.00115*(M29/10)))) -> 299.58107 | AZ29: =((AY29/10)*100)/BC29 -> 89.137527 | BA29: =(243.5*LN((AY29/10)/6.112))/(17.67-LN((AY29/10)/6.112))*10 -> 240.69869 | BC29: =6.112*2.718^((17.67*(L29/10))/((L29/10)+243.5)) -> 33.60886 | BD29: 1013.2 | BE29: =6.112*2.718^((17.67*(M29/10))/((M29/10)+243.5)) -> 30.920789
A30: 21 | B30: 19 | C30: 6 | D30: 4 | E30: 9 | F30: 9 | G30: 70 | H30: 1 | I30: 5 | J30: 22 | K30: 119 | L30: 275 | M30: 255 | N30: 311 | O30: 85 | P30: 247 | Q30: 1 | R30: 8 | S30: 3 | T30: 2 | U30: 1 | V30: 8 | W30: 63 | X30: 8 | Y30: 5 | Z30: 0 | AA30: 840 | AH30: hz | AN30: =N30-AY30 -> -1.4961819 | AO30: =O30-AZ30 -> -0.117106 | AP30: =P30-BA30 -> -0.74022003 | AY30: =10*(BE30-BD30*((L30/10)-(M30/10))*0.00066*(1+(0.00115*(M30/10)))) -> 312.49618 | AZ30: =((AY30/10)*100)/BC30 -> 85.117106 | BA30: =(243.5*LN((AY30/10)/6.112))/(17.67-LN((AY30/10)/6.112))*10 -> 247.74022 | BC30: =6.112*2.718^((17.67*(L30/10))/((L30/10)+243.5)) -> 36.713676 | BD30: 1013.2 | BE30: =6.112*2.718^((17.67*(M30/10))/((M30/10)+243.5)) -> 32.626262
A31: 22 | B31: 19 | C31: 1 | D31: 4 | E31: 6 | F31: 4 | G31: 70 | H31: 1 | I31: 5 | J31: 0 | K31: 116 | L31: 268 | M31: 240 | N31: 276 | O31: 78 | P31: 227 | Q31: 1 | R31: 8 | S31: 0 | T31: 0 | U31: 1 | V31: 8 | W31: 57 | X31: 8 | AH31: hz | AN31: =N31-AY31 -> -3.0356805 | AO31: =O31-AZ31 -> -1.1929967 | AP31: =P31-BA31 -> -1.9291319 | AY31: =10*(BE31-BD31*((L31/10)-(M31/10))*0.00066*(1+(0.00115*(M31/10)))) -> 279.03568 | AZ31: =((AY31/10)*100)/BC31 -> 79.192997 | BA31: =(243.5*LN((AY31/10)/6.112))/(17.67-LN((AY31/10)/6.112))*10 -> 228.92913 | BC31: =6.112*2.718^((17.67*(L31/10))/((L31/10)+243.5)) -> 35.234894 | BD31: 1013.2 | BE31: =6.112*2.718^((17.67*(M31/10))/((M31/10)+243.5)) -> 29.82764
A32: 23 | B32: 19 | C32: 7 | D32: 4 | E32: 9 | F32: 4 | G32: 80 | H32: 2 | K32: 110 | L32: 267 | M32: 243 | N32: 285 | O32: 81 | P32: 232 | Q32: 1 | R32: 2 | S32: 0 | T32: 2 | U32: 1 | V32: 8 | W32: 66 | X32: 8 | Y32: 7 | Z32: 0 | AA32: 870 | AN32: =N32-AY32 -> -2.2015031 | AO32: =O32-AZ32 -> -0.99209772 | AP32: =P32-BA32 -> -1.6950631 | AY32: =10*(BE32-BD32*((L32/10)-(M32/10))*0.00066*(1+(0.00115*(M32/10)))) -> 287.2015 | AZ32: =((AY32/10)*100)/BC32 -> 81.992098 | BA32: =(243.5*LN((AY32/10)/6.112))/(17.67-LN((AY32/10)/6.112))*10 -> 233.69506 | BC32: =6.112*2.718^((17.67*(L32/10))/((L32/10)+243.5)) -> 35.027949 | BD32: 1013.2 | BE32: =6.112*2.718^((17.67*(M32/10))/((M32/10)+243.5)) -> 30.369908
A33: 24 | B33: 19 | C33: 7 | D33: 4 | E33: 8 | F33: 10 | G33: 60 | H33: 1 | I33: 80 | J33: 22 | K33: 115 | L33: 256 | M33: 245 | N33: 300 | O33: 92 | P33: 241 | Q33: 6 | R33: 8 | S33: 0 | T33: 2 | U33: 4 | V33: 8 | W33: 48 | X33: 8 | Y33: 5 | Z33: 6 | AA33: 114 | AH33: jp-n,s,ne, pro @ 18:52-58 | AN33: =N33-AY33 -> 0.20110421 | AO33: =O33-AZ33 -> 0.65567228 | AP33: =P33-BA33 -> 0.18035757 | AY33: =10*(BE33-BD33*((L33/10)-(M33/10))*0.00066*(1+(0.00115*(M33/10)))) -> 299.7989 | AZ33: =((AY33/10)*100)/BC33 -> 91.344328 | BA33: =(243.5*LN((AY33/10)/6.112))/(17.67-LN((AY33/10)/6.112))*10 -> 240.81964 | BC33: =6.112*2.718^((17.67*(L33/10))/((L33/10)+243.5)) -> 32.820746 | BD33: 1013.2 | BE33: =6.112*2.718^((17.67*(M33/10))/((M33/10)+243.5)) -> 30.736198
A34: 25 | B34: 19 | C34: 6 | D34: 4 | E34: 7 | F34: 4 | G34: 76 | H34: 2 | K34: 127 | L34: 265 | M34: 234 | N34: 264 | O34: 76 | P34: 219 | Q34: 6 | R34: 8 | S34: 0 | T34: 2 | U34: 1 | V34: 8 | W34: 60 | X34: 8 | Y34: 6 | Z34: 6 | AA34: =45*3 -> 135 | AN34: =N34-AY34 -> -2.3968943 | AO34: =O34-AZ34 -> -0.95496351 | AP34: =P34-BA34 -> -2.3059324 | AY34: =10*(BE34-BD34*((L34/10)-(M34/10))*0.00066*(1+(0.00115*(M34/10)))) -> 266.39689 | AZ34: =((AY34/10)*100)/BC34 -> 76.954964 | BA34: =(243.5*LN((AY34/10)/6.112))/(17.67-LN((AY34/10)/6.112))*10 -> 221.30593 | BC34: =6.112*2.718^((17.67*(L34/10))/((L34/10)+243.5)) -> 34.617247 | BD34: 1013.2 | BE34: =6.112*2.718^((17.67*(M34/10))/((M34/10)+243.5)) -> 28.768481
A35: 26 | B35: 19 | C35: 4 | D35: 4 | E35: 5 | F35: 10 | G35: 75 | H35: 2 | K35: 125 | L35: 268 | M35: 248 | N35: 296 | O35: 84 | P35: 239 | Q35: 3 | R35: 8 | S35: 0 | T35: 2 | U35: 1 | V35: 8 | W35: 54 | X35: 8 | Y35: 3 | Z35: 6 | AA35: 114 | AN35: =N35-AY35 -> -3.1731607 | AO35: =O35-AZ35 -> -0.9082063 | AP35: =P35-BA35 -> -1.4719976 | AY35: =10*(BE35-BD35*((L35/10)-(M35/10))*0.00066*(1+(0.00115*(M35/10)))) -> 299.17316 | AZ35: =((AY35/10)*100)/BC35 -> 84.908206 | BA35: =(243.5*LN((AY35/10)/6.112))/(17.67-LN((AY35/10)/6.112))*10 -> 240.472 | BC35: =6.112*2.718^((17.67*(L35/10))/((L35/10)+243.5)) -> 35.234894 | BD35: 1013.2 | BE35: =6.112*2.718^((17.67*(M35/10))/((M35/10)+243.5)) -> 31.292883
A36: 27 | B36: 19 | C36: 7 | D36: 4 | E36: 8 | F36: 8 | G36: 68 | H36: 1 | I36: 5 | J36: 22 | K36: 128 | L36: 261 | M36: 245 | N36: 295 | O36: 87 | P36: 238 | Q36: 5 | R36: 8 | S36: 4 | T36: 1 | U36: 1 | V36: 8 | W36: 54 | X36: 8 | Y36: 4 | Z36: 6 | AA36: 105 | AH36: hz | AN36: =N36-AY36 -> -1.361131 | AO36: =O36-AZ36 -> -0.6588768 | AP36: =P36-BA36 -> -0.9017913 | AY36: =10*(BE36-BD36*((L36/10)-(M36/10))*0.00066*(1+(0.00115*(M36/10)))) -> 296.36113 | AZ36: =((AY36/10)*100)/BC36 -> 87.658877 | BA36: =(243.5*LN((AY36/10)/6.112))/(17.67-LN((AY36/10)/6.112))*10 -> 238.90179 | BC36: =6.112*2.718^((17.67*(L36/10))/((L36/10)+243.5)) -> 33.808456 | BD36: 1013.2 | BE36: =6.112*2.718^((17.67*(M36/10))/((M36/10)+243.5)) -> 30.736198
A37: 28 | B37: 19 | C37: 3 | D37: 4 | E37: 8 | F37: 12 | G37: 65 | H37: 1 | I37: 5 | J37: 0 | K37: 138 | L37: 270 | M37: 250 | N37: 300 | O37: 84 | P37: 241 | Q37: 2 | R37: 8 | S37: 3 | T37: 0 | U37: 2 | V37: 8 | W37: 60 | X37: 8 | AH37: hz | AN37: =N37-AY37 -> -2.9301667 | AO37: =O37-AZ37 -> -0.96865233 | AP37: =P37-BA37 -> -1.5498225 | AY37: =10*(BE37-BD37*((L37/10)-(M37/10))*0.00066*(1+(0.00115*(M37/10)))) -> 302.93017 | AZ37: =((AY37/10)*100)/BC37 -> 84.968652 | BA37: =(243.5*LN((AY37/10)/6.112))/(17.67-LN((AY37/10)/6.112))*10 -> 242.54982 | BC37: =6.112*2.718^((17.67*(L37/10))/((L37/10)+243.5)) -> 35.651991 | BD37: 1013.2 | BE37: =6.112*2.718^((17.67*(M37/10))/((M37/10)+243.5)) -> 31.668892
A38: 29 | B38: 19 | C38: 6 | D38: 4 | E38: 7 | F38: 12 | G38: 58 | H38: 1 | I38: 15 | J38: 22 | K38: 133 | L38: 260 | M38: 240 | N38: 283 | O38: 84 | P38: 231 | Q38: 6 | R38: 8 | S38: / | T38: / | U38: 2 | V38: 8 | W38: 51 | X38: 8 | Y38: 6 | Z38: 6 | AA38: 105 | AH38: jp-ne hz | AN38: =N38-AY38 -> -1.5330281 | AO38: =O38-AZ38 -> -0.66012412 | AP38: =P38-BA38 -> -1.1508299 | AY38: =10*(BE38-BD38*((L38/10)-(M38/10))*0.00066*(1+(0.00115*(M38/10)))) -> 284.53303 | AZ38: =((AY38/10)*100)/BC38 -> 84.660124 | BA38: =(243.5*LN((AY38/10)/6.112))/(17.67-LN((AY38/10)/6.112))*10 -> 232.15083 | BC38: =6.112*2.718^((17.67*(L38/10))/((L38/10)+243.5)) -> 33.60886 | BD38: 1013.2 | BE38: =6.112*2.718^((17.67*(M38/10))/((M38/10)+243.5)) -> 29.82764
A39: 30 | B39: 19 | C39: 7 | D39: 4 | E39: 7 | F39: 8 | G39: 70 | H39: 1 | I39: 5 | J39: 82 | K39: 114 | L39: 258 | M39: 230 | N39: 260 | O39: 78 | P39: 216 | Q39: 7 | R39: 8 | S39: 4 | T39: 0 | U39: 4 | V39: 8 | W39: 51 | X39: 8 | Y39: 5 | Z39: 6 | AA39: 105 | AH39: pro @ 18:01-08 | AN39: =N39-AY39 -> -1.588952 | AO39: =O39-AZ39 -> -0.76158661 | AP39: =P39-BA39 -> -2.3225317 | AY39: =10*(BE39-BD39*((L39/10)-(M39/10))*0.00066*(1+(0.00115*(M39/10)))) -> 261.58895 | AZ39: =((AY39/10)*100)/BC39 -> 78.761587 | BA39: =(243.5*LN((AY39/10)/6.112))/(17.67-LN((AY39/10)/6.112))*10 -> 218.32253 | BC39: =6.112*2.718^((17.67*(L39/10))/((L39/10)+243.5)) -> 33.212758 | BD39: 1013.2 | BE39: =6.112*2.718^((17.67*(M39/10))/((M39/10)+243.5)) -> 28.080814
AY40: =10*(BE40-BD40*((L40/10)-(M40/10))*0.00066*(1+(0.00115*(M40/10)))) -> 61.12 | AZ40: =((AY40/10)*100)/BC40 -> 100 | BA40: =(243.5*LN((AY40/10)/6.112))/(17.67-LN((AY40/10)/6.112))*10 -> 0 | BC40: =6.112*2.718^((17.67*(L40/10))/((L40/10)+243.5)) -> 6.112 | BD40: 1013.2 | BE40: =6.112*2.718^((17.67*(M40/10))/((M40/10)+243.5)) -> 6.112
AH41: Checked by VBA: 10:16:24 AM 3/17/2020
A42: SUM | C42: =SUM(C10:C40) -> 144 | F42: =SUM(F10:F40) -> 276 | K42: =SUM(K10:K40) -> 3597 | L42: =SUM(L10:L40) -> 8003 | M42: =SUM(M10:M40) -> 7289 | N42: =SUM(N10:N40) -> 8555 | O42: =SUM(O10:O40) -> 2443 | P42: =SUM(P10:P40) -> 6965 | Q42: =SUM(Q10:Q40) -> 80 | AH42: Checked by: F. Frank
A43: MEANS | C43: =AVERAGE(C10:C40) -> 4.8 | E43: =MODE(E10:E40) -> 9 | F43: =AVERAGE(F10:F40) -> 9.2 | K43: =AVERAGE(K10:K40) -> 119.9 | L43: =AVERAGE(L10:L40) -> 266.76667 | M43: =AVERAGE(M10:M40) -> 242.96667 | N43: =AVERAGE(N10:N40) -> 285.16667 | O43: =AVERAGE(O10:O40) -> 81.433333 | P43: =AVERAGE(P10:P40) -> 232.16667 | Q43: =AVERAGE(Q10:Q40) -> 2.6666667 | AN43: =AVERAGE(AN10:AN40) -> -2.2859795 | AO43: =AVERAGE(AO10:AO40) -> -0.78005409 | AP43: =AVERAGE(AP10:AP40) -> -1.5189036

Sheet 2200z
E7: WIND | L7: TEMP AND HUMIDITY | Q7: CLOUDS | U7: CLOUDS REPORTED BY 8NsChshs GROUPS | AH7: REMARKS | AN7: S.rule - Formula | AY7: Formula
A8: DAY | B8: HOUR | C8: Total cloud Amt. | D8: Wind indicator | E8: DIRECTION | F8: SPEED | G8: VISIBILITY | H8: Weather Indicator | I8: PRESENT WEATHER | J8: PAST WEATHER | K8: SEA LEVEL PRESSURE | L8: Dry Bulb | M8: Wet Bulb | N8: Vapour Pressure | O8: Relative humidity | P8: Dew Point | Q8: Total amt. Nh | R8: Form of CL | S8: Form of CM | T8: Form of CH | U8: Lowest layer | X8: 3/8 or more | AB8: 5/8 or more | AE8: Cb cloud | AN8: Vapour Pressure | AO8: Relative humidity | AP8: Dew Point | AY8: Vapour Pressure | AZ8: Relative humidity | BA8: Dew Point
U9: Amount | V9: Form | W9: Height | X9: Indicator | Y9: Amount | Z9: Form | AA9: Height | AB9: Amount | AC9: Form | AD9: Height | AE9: Amount | AF9: Form | AG9: Height | BC9: ####### | BD9: ********* | BE9: &&&&&&
A10: 1 | B10: 18 | C10: 4 | D10: 4 | E10: 8 | F10: 11 | G10: 76 | H10: 2 | K10: 125 | L10: 276 | M10: 244 | N10: 279 | O10: 75 | P10: 229 | Q10: 1 | R10: 8 | S10: 0 | T10: 2 | U10: 1 | V10: 8 | W10: 66 | X10: 8 | Y10: 3 | Z10: 0 | AA10: 840 | AN10: =N10-AY10 -> -4.5264912 | AO10: =O10-AZ10 -> -1.7754911 | AP10: =P10-BA10 -> -2.5650553 | AY10: =10*(BE10-BD10*((L10/10)-(M10/10))*0.00066*(1+(0.00115*(M10/10)))) -> 283.52649 | AZ10: =((AY10/10)*100)/BC10 -> 76.775491 | BA10: =(243.5*LN((AY10/10)/6.112))/(17.67-LN((AY10/10)/6.112))*10 -> 231.56506 | BC10: =6.112*2.718^((17.67*(L10/10))/((L10/10)+243.5)) -> 36.929297 | BD10: 1013.2 | BE10: =6.112*2.718^((17.67*(M10/10))/((M10/10)+243.5)) -> 30.552573
A11: 2 | B11: 18 | C11: 3 | D11: 4 | E11: 7 | F11: 10 | G11: 75 | H11: 2 | K11: 117 | L11: 278 | M11: 248 | N11: 290 | O11: 77 | P11: 235 | Q11: 2 | R11: 2 | S11: 0 | T11: 1 | U11: 2 | V11: 8 | W11: 60 | X11: 8 | AN11: =N11-AY11 -> -2.2953241 | AO11: =O11-AZ11 -> -1.2294191 | AP11: =P11-BA11 -> -1.6082611 | AY11: =10*(BE11-BD11*((L11/10)-(M11/10))*0.00066*(1+(0.00115*(M11/10)))) -> 292.29532 | AZ11: =((AY11/10)*100)/BC11 -> 78.229419 | BA11: =(243.5*LN((AY11/10)/6.112))/(17.67-LN((AY11/10)/6.112))*10 -> 236.60826 | BC11: =6.112*2.718^((17.67*(L11/10))/((L11/10)+243.5)) -> 37.363862 | BD11: 1013.2 | BE11: =6.112*2.718^((17.67*(M11/10))/((M11/10)+243.5)) -> 31.292883
A12: 3 | B12: 18 | C12: 2 | D12: 4 | E12: 9 | F12: 7 | G12: 75 | H12: 2 | K12: 121 | L12: 279 | M12: 245 | N12: 282 | O12: 75 | P12: 230 | Q12: 1 | R12: 2 | S12: 0 | T12: 2 | U12: 1 | V12: 8 | W12: 63 | X12: 8 | AN12: =N12-AY12 -> -1.9851777 | AO12: =O12-AZ12 -> -0.56250683 | AP12: =P12-BA12 -> -1.8322228 | AY12: =10*(BE12-BD12*((L12/10)-(M12/10))*0.00066*(1+(0.00115*(M12/10)))) -> 283.98518 | AZ12: =((AY12/10)*100)/BC12 -> 75.562507 | BA12: =(243.5*LN((AY12/10)/6.112))/(17.67-LN((AY12/10)/6.112))*10 -> 231.83222 | BC12: =6.112*2.718^((17.67*(L12/10))/((L12/10)+243.5)) -> 37.582816 | BD12: 1013.2 | BE12: =6.112*2.718^((17.67*(M12/10))/((M12/10)+243.5)) -> 30.736198
A13: 4 | B13: 18 | C13: 2 | D13: 4 | E13: 11 | F13: 13 | G13: 80 | H13: 2 | K13: 124 | L13: 275 | M13: 250 | N13: 297 | O13: 81 | P13: 239 | Q13: 1 | R13: 2 | S13: 0 | T13: 2 | U13: 1 | V13: 8 | W13: 66 | X13: 8 | AN13: =N13-AY13 -> -2.4904793 | AO13: =O13-AZ13 -> -0.57463787 | AP13: =P13-BA13 -> -1.6483724 | AY13: =10*(BE13-BD13*((L13/10)-(M13/10))*0.00066*(1+(0.00115*(M13/10)))) -> 299.49048 | AZ13: =((AY13/10)*100)/BC13 -> 81.574638 | BA13: =(243.5*LN((AY13/10)/6.112))/(17.67-LN((AY13/10)/6.112))*10 -> 240.64837 | BC13: =6.112*2.718^((17.67*(L13/10))/((L13/10)+243.5)) -> 36.713676 | BD13: 1013.2 | BE13: =6.112*2.718^((17.67*(M13/10))/((M13/10)+243.5)) -> 31.668892
A14: 5 | B14: 18 | C14: 6 | D14: 4 | E14: 9 | F14: 10 | G14: 78 | H14: 2 | K14: 119 | L14: 279 | M14: 246 | N14: 287 | O14: 75 | P14: 231 | Q14: 1 | R14: 1 | S14: 0 | T14: 1 | U14: 1 | V14: 8 | W14: 60 | X14: 8 | Y14: 5 | Z14: 0 | AA14: 900 | AN14: =N14-AY14 -> 0.48389985 | AO14: =O14-AZ14 -> -1.2359323 | AP14: =P14-BA14 -> -2.2996272 | AY14: =10*(BE14-BD14*((L14/10)-(M14/10))*0.00066*(1+(0.00115*(M14/10)))) -> 286.5161 | AZ14: =((AY14/10)*100)/BC14 -> 76.235932 | BA14: =(243.5*LN((AY14/10)/6.112))/(17.67-LN((AY14/10)/6.112))*10 -> 233.29963 | BC14: =6.112*2.718^((17.67*(L14/10))/((L14/10)+243.5)) -> 37.582816 | BD14: 1013.2 | BE14: =6.112*2.718^((17.67*(M14/10))/((M14/10)+243.5)) -> 30.920789
A15: 6 | B15: 18 | C15: 2 | D15: 4 | E15: 10 | F15: 14 | G15: 80 | H15: 2 | K15: 115 | L15: 277 | M15: 245 | N15: 284 | O15: 76 | P15: 231 | Q15: 1 | R15: 1 | S15: 0 | T15: 1 | U15: 1 | V15: 8 | W15: 66 | X15: 8 | AN15: =N15-AY15 -> -1.3602836 | AO15: =O15-AZ15 -> -0.82121826 | AP15: =P15-BA15 -> -1.6309106 | AY15: =10*(BE15-BD15*((L15/10)-(M15/10))*0.00066*(1+(0.00115*(M15/10)))) -> 285.36028 | AZ15: =((AY15/10)*100)/BC15 -> 76.821218 | BA15: =(243.5*LN((AY15/10)/6.112))/(17.67-LN((AY15/10)/6.112))*10 -> 232.63091 | BC15: =6.112*2.718^((17.67*(L15/10))/((L15/10)+243.5)) -> 37.146024 | BD15: 1013.2 | BE15: =6.112*2.718^((17.67*(M15/10))/((M15/10)+243.5)) -> 30.736198
A16: 7 | B16: 18 | C16: 4 | D16: 4 | E16: 10 | F16: 11 | G16: 76 | H16: 2 | K16: 105 | L16: 275 | M16: 239 | N16: 269 | O16: 73 | P16: 222 | Q16: 1 | R16: 2 | S16: 0 | T16: 2 | U16: 1 | V16: 8 | W16: 69 | X16: 8 | Y16: 4 | Z16: 0 | AA16: 840 | AN16: =N16-AY16 -> -2.7524785 | AO16: =O16-AZ16 -> -1.0194148 | AP16: =P16-BA16 -> -2.5740902 | AY16: =10*(BE16-BD16*((L16/10)-(M16/10))*0.00066*(1+(0.00115*(M16/10)))) -> 271.75248 | AZ16: =((AY16/10)*100)/BC16 -> 74.019415 | BA16: =(243.5*LN((AY16/10)/6.112))/(17.67-LN((AY16/10)/6.112))*10 -> 224.57409 | BC16: =6.112*2.718^((17.67*(L16/10))/((L16/10)+243.5)) -> 36.713676 | BD16: 1013.2 | BE16: =6.112*2.718^((17.67*(M16/10))/((M16/10)+243.5)) -> 29.648777
A17: 8 | B17: 18 | C17: 1 | D17: 4 | E17: 10 | F17: 13 | G17: 75 | H17: 2 | K17: 110 | L17: 278 | M17: 250 | N17: 295 | O17: 79 | P17: 238 | Q17: 1 | R17: 8 | S17: 0 | T17: 0 | U17: 1 | V17: 8 | W17: 63 | X17: 8 | AN17: =N17-AY17 -> -2.4266669 | AO17: =O17-AZ17 -> -0.60276291 | AP17: =P17-BA17 -> -1.4983038 | AY17: =10*(BE17-BD17*((L17/10)-(M17/10))*0.00066*(1+(0.00115*(M17/10)))) -> 297.42667 | AZ17: =((AY17/10)*100)/BC17 -> 79.602763 | BA17: =(243.5*LN((AY17/10)/6.112))/(17.67-LN((AY17/10)/6.112))*10 -> 239.4983 | BC17: =6.112*2.718^((17.67*(L17/10))/((L17/10)+243.5)) -> 37.363862 | BD17: 1013.2 | BE17: =6.112*2.718^((17.67*(M17/10))/((M17/10)+243.5)) -> 31.668892
A18: 9 | B18: 18 | C18: 6 | D18: 4 | E18: 9 | F18: 13 | G18: 78 | H18: 2 | K18: 111 | L18: 276 | M18: 250 | N18: 297 | O18: 80 | P18: 239 | Q18: 1 | R18: 2 | S18: 0 | T18: 1 | U18: 1 | V18: 8 | W18: 66 | X18: 8 | Y18: 6 | Z18: 0 | AA18: 900 | AN18: =N18-AY18 -> -1.8025419 | AO18: =O18-AZ18 -> -0.91205802 | AP18: =P18-BA18 -> -1.2657894 | AY18: =10*(BE18-BD18*((L18/10)-(M18/10))*0.00066*(1+(0.00115*(M18/10)))) -> 298.80254 | AZ18: =((AY18/10)*100)/BC18 -> 80.912058 | BA18: =(243.5*LN((AY18/10)/6.112))/(17.67-LN((AY18/10)/6.112))*10 -> 240.26579 | BC18: =6.112*2.718^((17.67*(L18/10))/((L18/10)+243.5)) -> 36.929297 | BD18: 1013.2 | BE18: =6.112*2.718^((17.67*(M18/10))/((M18/10)+243.5)) -> 31.668892
A19: 10 | B19: 18 | C19: 5 | D19: 4 | E19: 8 | F19: 12 | G19: 75 | H19: 2 | K19: 89 | L19: 281 | M19: 252 | N19: 297 | O19: 78 | P19: 239 | Q19: 1 | R19: 2 | S19: 0 | T19: 1 | U19: 1 | V19: 8 | W19: 66 | X19: 8 | Y19: 7 | Z19: 0 | AA19: 900 | AN19: =N19-AY19 -> -3.5338329 | AO19: =O19-AZ19 -> -1.0377474 | AP19: =P19-BA19 -> -2.2271472 | AY19: =10*(BE19-BD19*((L19/10)-(M19/10))*0.00066*(1+(0.00115*(M19/10)))) -> 300.53383 | AZ19: =((AY19/10)*100)/BC19 -> 79.037747 | BA19: =(243.5*LN((AY19/10)/6.112))/(17.67-LN((AY19/10)/6.112))*10 -> 241.22715 | BC19: =6.112*2.718^((17.67*(L19/10))/((L19/10)+243.5)) -> 38.024089 | BD19: 1013.2 | BE19: =6.112*2.718^((17.67*(M19/10))/((M19/10)+243.5)) -> 32.048848
A20: 11 | B20: 18 | C20: 7 | D20: 4 | E20: 11 | F20: 7 | G20: 68 | H20: 1 | I20: 5 | J20: 22 | K20: 94 | L20: 278 | M20: 248 | N20: 290 | O20: 77 | P20: 235 | Q20: 2 | R20: 8 | S20: 0 | T20: 2 | U20: 2 | V20: 8 | W20: 57 | X20: 8 | Y20: 7 | Z20: 0 | AA20: 840 | AH20: hz | AN20: =N20-AY20 -> -2.2953241 | AO20: =O20-AZ20 -> -1.2294191 | AP20: =P20-BA20 -> -1.6082611 | AY20: =10*(BE20-BD20*((L20/10)-(M20/10))*0.00066*(1+(0.00115*(M20/10)))) -> 292.29532 | AZ20: =((AY20/10)*100)/BC20 -> 78.229419 | BA20: =(243.5*LN((AY20/10)/6.112))/(17.67-LN((AY20/10)/6.112))*10 -> 236.60826 | BC20: =6.112*2.718^((17.67*(L20/10))/((L20/10)+243.5)) -> 37.363862 | BD20: 1013.2 | BE20: =6.112*2.718^((17.67*(M20/10))/((M20/10)+243.5)) -> 31.292883
A21: 12 | B21: 18 | C21: 7 | D21: 4 | E21: 8 | F21: 9 | G21: 75 | H21: 2 | K21: 112 | L21: 277 | M21: 240 | N21: 270 | O21: 73 | P21: 223 | Q21: 3 | R21: 8 | S21: 4 | T21: 2 | U21: 1 | V21: 8 | W21: 66 | X21: 8 | Y21: 7 | Z21: 0 | AA21: 840 | AN21: =N21-AY21 -> -2.8511644 | AO21: =O21-AZ21 -> -0.45366563 | AP21: =P21-BA21 -> -2.2375592 | AY21: =10*(BE21-BD21*((L21/10)-(M21/10))*0.00066*(1+(0.00115*(M21/10)))) -> 272.85116 | AZ21: =((AY21/10)*100)/BC21 -> 73.453666 | BA21: =(243.5*LN((AY21/10)/6.112))/(17.67-LN((AY21/10)/6.112))*10 -> 225.23756 | BC21: =6.112*2.718^((17.67*(L21/10))/((L21/10)+243.5)) -> 37.146024 | BD21: 1013.2 | BE21: =6.112*2.718^((17.67*(M21/10))/((M21/10)+243.5)) -> 29.82764
A22: 13 | B22: 18 | C22: 1 | D22: 4 | E22: 6 | F22: 12 | G22: 80 | H22: 2 | K22: 119 | L22: 280 | M22: 240 | N22: 266 | O22: 70 | P22: 221 | Q22: 1 | R22: 2 | S22: 0 | T22: 1 | U22: 1 | V22: 8 | W22: 63 | X22: 8 | AN22: =N22-AY22 -> -4.7896591 | AO22: =O22-AZ22 -> -1.6319998 | AP22: =P22-BA22 -> -2.9907322 | AY22: =10*(BE22-BD22*((L22/10)-(M22/10))*0.00066*(1+(0.00115*(M22/10)))) -> 270.78966 | AZ22: =((AY22/10)*100)/BC22 -> 71.632 | BA22: =(243.5*LN((AY22/10)/6.112))/(17.67-LN((AY22/10)/6.112))*10 -> 223.99073 | BC22: =6.112*2.718^((17.67*(L22/10))/((L22/10)+243.5)) -> 37.80289 | BD22: 1013.2 | BE22: =6.112*2.718^((17.67*(M22/10))/((M22/10)+243.5)) -> 29.82764
A23: 14 | B23: 18 | C23: 7 | D23: 4 | E23: 7 | F23: 12 | G23: 78 | H23: 2 | K23: 114 | L23: 277 | M23: 236 | N23: 259 | O23: 70 | P23: 217 | Q23: 1 | R23: 8 | S23: 6 | T23: 1 | U23: 1 | V23: 8 | W23: 60 | X23: 8 | Y23: 6 | Z23: 0 | AA23: 840 | AN23: =N23-AY23 -> -4.016839 | AO23: =O23-AZ23 -> -0.80618836 | AP23: =P23-BA23 -> -2.213541 | AY23: =10*(BE23-BD23*((L23/10)-(M23/10))*0.00066*(1+(0.00115*(M23/10)))) -> 263.01684 | AZ23: =((AY23/10)*100)/BC23 -> 70.806188 | BA23: =(243.5*LN((AY23/10)/6.112))/(17.67-LN((AY23/10)/6.112))*10 -> 219.21354 | BC23: =6.112*2.718^((17.67*(L23/10))/((L23/10)+243.5)) -> 37.146024 | BD23: 1013.2 | BE23: =6.112*2.718^((17.67*(M23/10))/((M23/10)+243.5)) -> 29.117813
A24: 15 | B24: 18 | C24: 2 | D24: 4 | E24: 9 | F24: 12 | G24: 78 | H24: 2 | K24: 108 | L24: 281 | M24: 230 | N24: 240 | O24: 63 | P24: 204 | Q24: 1 | R24: 1 | S24: 0 | T24: 1 | U24: 1 | V24: 8 | W24: 66 | X24: 8 | AN24: =N24-AY24 -> -5.801765 | AO24: =O24-AZ24 -> -1.6436962 | AP24: =P24-BA24 -> -4.1761063 | AY24: =10*(BE24-BD24*((L24/10)-(M24/10))*0.00066*(1+(0.00115*(M24/10)))) -> 245.80177 | AZ24: =((AY24/10)*100)/BC24 -> 64.643696 | BA24: =(243.5*LN((AY24/10)/6.112))/(17.67-LN((AY24/10)/6.112))*10 -> 208.17611 | BC24: =6.112*2.718^((17.67*(L24/10))/((L24/10)+243.5)) -> 38.024089 | BD24: 1013.2 | BE24: =6.112*2.718^((17.67*(M24/10))/((M24/10)+243.5)) -> 28.080814
A25: 16 | B25: 18 | C25: 6 | D25: 4 | E25: 9 | F25: 11 | G25: 68 | H25: 1 | I25: 15 | J25: 22 | K25: 125 | L25: 280 | M25: 246 | N25: 283 | O25: 75 | P25: 231 | Q25: 4 | R25: 8 | S25: 0 | T25: 2 | U25: 3 | V25: 8 | W25: 54 | X25: 8 | Y25: 5 | Z25: 0 | AA25: 840 | AH25: tcu-ene, jp-ene | AN25: =N25-AY25 -> -2.8284703 | AO25: =O25-AZ25 -> -0.61021717 | AP25: =P25-BA25 -> -1.9020731 | AY25: =10*(BE25-BD25*((L25/10)-(M25/10))*0.00066*(1+(0.00115*(M25/10)))) -> 285.82847 | AZ25: =((AY25/10)*100)/BC25 -> 75.610217 | BA25: =(243.5*LN((AY25/10)/6.112))/(17.67-LN((AY25/10)/6.112))*10 -> 232.90207 | BC25: =6.112*2.718^((17.67*(L25/10))/((L25/10)+243.5)) -> 37.80289 | BD25: 1013.2 | BE25: =6.112*2.718^((17.67*(M25/10))/((M25/10)+243.5)) -> 30.920789
A26: 17 | B26: 18 | C26: 8 | D26: 4 | E26: 0 | F26: 0 | G26: 70 | H26: 1 | I26: 5 | J26: 62 | K26: 139 | L26: 241 | M26: 231 | N26: 274 | O26: 91 | P26: 226 | Q26: 6 | R26: 8 | S26: 4 | T26: 2 | U26: 3 | V26: 8 | W26: 45 | X26: 8 | Y26: 6 | Z26: 6 | AA26: 105 | AH26: hz; ro ---> roro 17:05-17:30 | AN26: =N26-AY26 -> -1.6488988 | AO26: =O26-AZ26 -> -0.86016616 | AP26: =P26-BA26 -> -0.91652905 | AY26: =10*(BE26-BD26*((L26/10)-(M26/10))*0.00066*(1+(0.00115*(M26/10)))) -> 275.6489 | AZ26: =((AY26/10)*100)/BC26 -> 91.860166 | BA26: =(243.5*LN((AY26/10)/6.112))/(17.67-LN((AY26/10)/6.112))*10 -> 226.91653 | BC26: =6.112*2.718^((17.67*(L26/10))/((L26/10)+243.5)) -> 30.007446 | BD26: 1013.2 | BE26: =6.112*2.718^((17.67*(M26/10))/((M26/10)+243.5)) -> 28.251366
A27: 18 | B27: 18 | C27: 5 | D27: 4 | E27: 7 | F27: 8 | G27: 68 | H27: 1 | I27: 15 | J27: 82 | K27: 133 | L27: 271 | M27: 249 | N27: 297 | O27: 83 | P27: 239 | Q27: 4 | R27: 4 | S27: 0 | T27: 2 | U27: 2 | V27: 8 | W27: 54 | X27: 8 | Y27: 3 | Z27: 6 | AA27: 120 | AH27: pro @ 17:16-21 jp-ne hz | AN27: =N27-AY27 -> -2.6710292 | AO27: =O27-AZ27 -> -0.56191485 | AP27: =P27-BA27 -> -1.7486542 | AY27: =10*(BE27-BD27*((L27/10)-(M27/10))*0.00066*(1+(0.00115*(M27/10)))) -> 299.67103 | AZ27: =((AY27/10)*100)/BC27 -> 83.561915 | BA27: =(243.5*LN((AY27/10)/6.112))/(17.67-LN((AY27/10)/6.112))*10 -> 240.74865 | BC27: =6.112*2.718^((17.67*(L27/10))/((L27/10)+243.5)) -> 35.862154 | BD27: 1013.2 | BE27: =6.112*2.718^((17.67*(M27/10))/((M27/10)+243.5)) -> 31.480396
A28: 19 | B28: 18 | C28: 3 | D28: 4 | E28: 7 | F28: 12 | G28: 72 | H28: 1 | I28: 5 | J28: 11 | K28: 110 | L28: 280 | M28: 247 | N28: 285 | O28: 75 | P28: 232 | Q28: 2 | R28: 8 | S28: 3 | T28: 1 | U28: 1 | V28: 8 | W28: 60 | X28: 8 | AH28: hz | AN28: =N28-AY28 -> -3.3691666 | AO28: =O28-AZ28 -> -1.2823077 | AP28: =P28-BA28 -> -2.3668342 | AY28: =10*(BE28-BD28*((L28/10)-(M28/10))*0.00066*(1+(0.00115*(M28/10)))) -> 288.36917 | AZ28: =((AY28/10)*100)/BC28 -> 76.282308 | BA28: =(243.5*LN((AY28/10)/6.112))/(17.67-LN((AY28/10)/6.112))*10 -> 234.36683 | BC28: =6.112*2.718^((17.67*(L28/10))/((L28/10)+243.5)) -> 37.80289 | BD28: 1013.2 | BE28: =6.112*2.718^((17.67*(M28/10))/((M28/10)+243.5)) -> 31.106349
A29: 20 | B29: 18 | C29: 7 | D29: 4 | E29: 11 | F29: 13 | G29: 62 | H29: 1 | I29: 5 | J29: 82 | K29: 110 | L29: 260 | M29: 250 | N29: 309 | O29: 92 | P29: 246 | Q29: 7 | R29: 8 | S29: 7 | T29: / | U29: 5 | V29: 8 | W29: 51 | X29: 8 | Y29: 6 | Z29: 4 | AA29: 240 | AH29: pro ended @ 17:05 hz | AN29: =N29-AY29 -> -0.8095414 | AO29: =O29-AZ29 -> -0.18091271 | AP29: =P29-BA29 -> -0.29668794 | AY29: =10*(BE29-BD29*((L29/10)-(M29/10))*0.00066*(1+(0.00115*(M29/10)))) -> 309.80954 | AZ29: =((AY29/10)*100)/BC29 -> 92.180913 | BA29: =(243.5*LN((AY29/10)/6.112))/(17.67-LN((AY29/10)/6.112))*10 -> 246.29669 | BC29: =6.112*2.718^((17.67*(L29/10))/((L29/10)+243.5)) -> 33.60886 | BD29: 1013.2 | BE29: =6.112*2.718^((17.67*(M29/10))/((M29/10)+243.5)) -> 31.668892
A30: 21 | B30: 18 | C30: 6 | D30: 4 | E30: 8 | F30: 9 | G30: 70 | H30: 1 | I30: 5 | J30: 22 | K30: 115 | L30: 280 | M30: 255 | N30: 308 | O30: 81 | P30: 245 | Q30: 1 | R30: 8 | S30: 3 | T30: 2 | U30: 1 | V30: 8 | W30: 63 | X30: 8 | Y30: 6 | Z30: 0 | AA30: 840 | AH30: hz | AN30: =N30-AY30 -> -1.054572 | AO30: =O30-AZ30 -> -0.75421883 | AP30: =P30-BA30 -> -0.88907081 | AY30: =10*(BE30-BD30*((L30/10)-(M30/10))*0.00066*(1+(0.00115*(M30/10)))) -> 309.05457 | AZ30: =((AY30/10)*100)/BC30 -> 81.754219 | BA30: =(243.5*LN((AY30/10)/6.112))/(17.67-LN((AY30/10)/6.112))*10 -> 245.88907 | BC30: =6.112*2.718^((17.67*(L30/10))/((L30/10)+243.5)) -> 37.80289 | BD30: 1013.2 | BE30: =6.112*2.718^((17.67*(M30/10))/((M30/10)+243.5)) -> 32.626262
A31: 22 | B31: 18 | C31: 4 | D31: 4 | E31: 7 | F31: 12 | G31: 70 | H31: 1 | I31: 5 | J31: 11 | K31: 117 | L31: 277 | M31: 237 | N31: 261 | O31: 70 | P31: 218 | Q31: 4 | R31: 8 | S31: 3 | T31: 1 | U31: 1 | V31: 8 | W31: 57 | X31: 8 | Y31: 4 | Z31: 6 | AA31: 120 | AH31: hz | AN31: =N31-AY31 -> -4.4611745 | AO31: =O31-AZ31 -> -1.4642226 | AP31: =P31-BA31 -> -2.7290241 | AY31: =10*(BE31-BD31*((L31/10)-(M31/10))*0.00066*(1+(0.00115*(M31/10)))) -> 265.46117 | AZ31: =((AY31/10)*100)/BC31 -> 71.464223 | BA31: =(243.5*LN((AY31/10)/6.112))/(17.67-LN((AY31/10)/6.112))*10 -> 220.72902 | BC31: =6.112*2.718^((17.67*(L31/10))/((L31/10)+243.5)) -> 37.146024 | BD31: 1013.2 | BE31: =6.112*2.718^((17.67*(M31/10))/((M31/10)+243.5)) -> 29.293868
A32: 23 | B32: 18 | C32: 7 | D32: 4 | E32: 0 | F32: 0 | G32: 80 | H32: 2 | K32: 108 | L32: 285 | M32: 250 | N32: 290 | O32: 74 | P32: 235 | Q32: 1 | R32: 2 | S32: 0 | T32: 2 | U32: 1 | V32: 8 | W32: 66 | X32: 8 | Y32: 7 | Z32: 0 | AA32: 870 | AN32: =N32-AY32 -> -2.6111046 | AO32: =O32-AZ32 -> -1.1822557 | AP32: =P32-BA32 -> -1.7873911 | AY32: =10*(BE32-BD32*((L32/10)-(M32/10))*0.00066*(1+(0.00115*(M32/10)))) -> 292.6111 | AZ32: =((AY32/10)*100)/BC32 -> 75.182256 | BA32: =(243.5*LN((AY32/10)/6.112))/(17.67-LN((AY32/10)/6.112))*10 -> 236.78739 | BC32: =6.112*2.718^((17.67*(L32/10))/((L32/10)+243.5)) -> 38.920235 | BD32: 1013.2 | BE32: =6.112*2.718^((17.67*(M32/10))/((M32/10)+243.5)) -> 31.668892
A33: 24 | B33: 18 | C33: 7 | D33: 4 | E33: 7 | F33: 5 | G33: 58 | H33: 1 | I33: 15 | J33: 82 | K33: 110 | L33: 255 | M33: 245 | N33: 300 | O33: 92 | P33: 241 | Q33: 6 | R33: 8 | S33: 0 | T33: 2 | U33: 3 | V33: 8 | W33: 48 | X33: 8 | Y33: 5 | Z33: 6 | AA33: 114 | AH33: pro @ 17:18-30, jp-s | AN33: =N33-AY33 -> -0.48644875 | AO33: =O33-AZ33 -> -0.099563028 | AP33: =P33-BA33 -> -0.20090014 | AY33: =10*(BE33-BD33*((L33/10)-(M33/10))*0.00066*(1+(0.00115*(M33/10)))) -> 300.48645 | AZ33: =((AY33/10)*100)/BC33 -> 92.099563 | BA33: =(243.5*LN((AY33/10)/6.112))/(17.67-LN((AY33/10)/6.112))*10 -> 241.2009 | BC33: =6.112*2.718^((17.67*(L33/10))/((L33/10)+243.5)) -> 32.626262 | BD33: 1013.2 | BE33: =6.112*2.718^((17.67*(M33/10))/((M33/10)+243.5)) -> 30.736198
A34: 25 | B34: 18 | C34: 7 | D34: 4 | E34: 7 | F34: 5 | G34: 76 | H34: 2 | K34: 121 | L34: 274 | M34: 233 | N34: 253 | O34: 69 | P34: 213 | Q34: 7 | R34: 8 | S34: 0 | T34: 2 | U34: 1 | V34: 8 | W34: 60 | X34: 8 | Y34: 7 | Z34: 6 | AA34: =45*3 -> 135 | AN34: =N34-AY34 -> -4.8001238 | AO34: =O34-AZ34 -> -1.6318052 | AP34: =P34-BA34 -> -2.937447 | AY34: =10*(BE34-BD34*((L34/10)-(M34/10))*0.00066*(1+(0.00115*(M34/10)))) -> 257.80012 | AZ34: =((AY34/10)*100)/BC34 -> 70.631805 | BA34: =(243.5*LN((AY34/10)/6.112))/(17.67-LN((AY34/10)/6.112))*10 -> 215.93745 | BC34: =6.112*2.718^((17.67*(L34/10))/((L34/10)+243.5)) -> 36.499155 | BD34: 1013.2 | BE34: =6.112*2.718^((17.67*(M34/10))/((M34/10)+243.5)) -> 28.595196
A35: 26 | B35: 18 | C35: 6 | D35: 4 | E35: 7 | F35: 10 | G35: 72 | H35: 1 | I35: 5 | J35: 22 | K35: 121 | L35: 273 | M35: 253 | N35: 306 | O35: 84 | P35: 244 | Q35: 4 | R35: 8 | S35: 4 | T35: 3 | U35: 1 | V35: 8 | W35: 54 | X35: 8 | Y35: 4 | Z35: 6 | AA35: 114 | AH35: hz | AN35: =N35-AY35 -> -2.6398134 | AO35: =O35-AZ35 -> -1.0581755 | AP35: =P35-BA35 -> -1.6647665 | AY35: =10*(BE35-BD35*((L35/10)-(M35/10))*0.00066*(1+(0.00115*(M35/10)))) -> 308.63981 | AZ35: =((AY35/10)*100)/BC35 -> 85.058176 | BA35: =(243.5*LN((AY35/10)/6.112))/(17.67-LN((AY35/10)/6.112))*10 -> 245.66477 | BC35: =6.112*2.718^((17.67*(L35/10))/((L35/10)+243.5)) -> 36.285732 | BD35: 1013.2 | BE35: =6.112*2.718^((17.67*(M35/10))/((M35/10)+243.5)) -> 32.240318
A36: 27 | B36: 18 | C36: 6 | D36: 4 | E36: 7 | F36: 11 | G36: 60 | H36: 1 | I36: 15 | J36: 22 | K36: 124 | L36: 263 | M36: 249 | N36: 304 | O36: 89 | P36: 243 | Q36: 4 | R36: 8 | S36: 0 | T36: 1 | U36: 1 | V36: 8 | W36: 54 | X36: 8 | Y36: 4 | Z36: 6 | AA36: 105 | AH36: jp-sw hz | AN36: =N36-AY36 -> -1.1739137 | AO36: =O36-AZ36 -> -0.20407014 | AP36: =P36-BA36 -> -0.77999785 | AY36: =10*(BE36-BD36*((L36/10)-(M36/10))*0.00066*(1+(0.00115*(M36/10)))) -> 305.17391 | AZ36: =((AY36/10)*100)/BC36 -> 89.20407 | BA36: =(243.5*LN((AY36/10)/6.112))/(17.67-LN((AY36/10)/6.112))*10 -> 243.78 | BC36: =6.112*2.718^((17.67*(L36/10))/((L36/10)+243.5)) -> 34.210761 | BD36: 1013.2 | BE36: =6.112*2.718^((17.67*(M36/10))/((M36/10)+243.5)) -> 31.480396
A37: 28 | B37: 18 | C37: 3 | D37: 4 | E37: 7 | F37: 12 | G37: 65 | H37: 1 | I37: 5 | J37: 0 | K37: 133 | L37: 274 | M37: 255 | N37: 311 | O37: 85 | P37: 247 | Q37: 2 | R37: 8 | S37: 3 | T37: 0 | U37: 2 | V37: 8 | W37: 63 | X37: 8 | AH37: hz | AN37: =N37-AY37 -> -2.1845039 | AO37: =O37-AZ37 -> -0.8059591 | AP37: =P37-BA37 -> -1.1083069 | AY37: =10*(BE37-BD37*((L37/10)-(M37/10))*0.00066*(1+(0.00115*(M37/10)))) -> 313.1845 | AZ37: =((AY37/10)*100)/BC37 -> 85.805959 | BA37: =(243.5*LN((AY37/10)/6.112))/(17.67-LN((AY37/10)/6.112))*10 -> 248.10831 | BC37: =6.112*2.718^((17.67*(L37/10))/((L37/10)+243.5)) -> 36.499155 | BD37: 1013.2 | BE37: =6.112*2.718^((17.67*(M37/10))/((M37/10)+243.5)) -> 32.626262
A38: 29 | B38: 18 | C38: 6 | D38: 4 | E38: 5 | F38: 10 | G38: 59 | H38: 1 | I38: 5 | J38: 22 | K38: 129 | L38: 257 | M38: 237 | N38: 279 | O38: 84 | P38: 228 | Q38: 6 | R38: 8 | S38: / | T38: / | U38: 2 | V38: 8 | W38: 54 | X38: 8 | Y38: 6 | Z38: 6 | AA38: 105 | AH38: cb-ne hz | AN38: =N38-AY38 -> -0.19992939 | AO38: =O38-AZ38 -> -0.56441579 | AP38: =P38-BA38 -> -1.026192 | AY38: =10*(BE38-BD38*((L38/10)-(M38/10))*0.00066*(1+(0.00115*(M38/10)))) -> 279.19993 | AZ38: =((AY38/10)*100)/BC38 -> 84.564416 | BA38: =(243.5*LN((AY38/10)/6.112))/(17.67-LN((AY38/10)/6.112))*10 -> 229.02619 | BC38: =6.112*2.718^((17.67*(L38/10))/((L38/10)+243.5)) -> 33.016243 | BD38: 1013.2 | BE38: =6.112*2.718^((17.67*(M38/10))/((M38/10)+243.5)) -> 29.293868
A39: 30 | B39: 18 | C39: 7 | D39: 4 | E39: 7 | F39: 15 | G39: 57 | H39: 1 | I39: 15 | J39: 22 | K39: 111 | L39: 269 | M39: 236 | N39: 265 | O39: 75 | P39: 220 | Q39: 7 | R39: 8 | S39: 4 | T39: 0 | U39: 4 | V39: 8 | W39: 45 | X39: 8 | Y39: 6 | Z39: 6 | AA39: 105 | AH39: jp-ene,ese | AN39: =N39-AY39 -> -3.5117257 | AO39: =O39-AZ39 -> -0.75894745 | AP39: =P39-BA39 -> -2.6032944 | AY39: =10*(BE39-BD39*((L39/10)-(M39/10))*0.00066*(1+(0.00115*(M39/10)))) -> 268.51173 | AZ39: =((AY39/10)*100)/BC39 -> 75.758947 | BA39: =(243.5*LN((AY39/10)/6.112))/(17.67-LN((AY39/10)/6.112))*10 -> 222.60329 | BC39: =6.112*2.718^((17.67*(L39/10))/((L39/10)+243.5)) -> 35.442906 | BD39: 1013.2 | BE39: =6.112*2.718^((17.67*(M39/10))/((M39/10)+243.5)) -> 29.117813
AY40: =10*(BE40-BD40*((L40/10)-(M40/10))*0.00066*(1+(0.00115*(M40/10)))) -> 61.12 | AZ40: =((AY40/10)*100)/BC40 -> 100 | BA40: =(243.5*LN((AY40/10)/6.112))/(17.67-LN((AY40/10)/6.112))*10 -> 0 | BC40: =6.112*2.718^((17.67*(L40/10))/((L40/10)+243.5)) -> 6.112 | BD40: 1013.2 | BE40: =6.112*2.718^((17.67*(M40/10))/((M40/10)+243.5)) -> 6.112
AH41: Checked by VBA: 10:16:24 AM 3/17/2020
A42: SUM | C42: =SUM(C10:C40) -> 147 | F42: =SUM(F10:F40) -> 299 | K42: =SUM(K10:K40) -> 3489 | L42: =SUM(L10:L40) -> 8206 | M42: =SUM(M10:M40) -> 7336 | N42: =SUM(N10:N40) -> 8527 | O42: =SUM(O10:O40) -> 2341 | P42: =SUM(P10:P40) -> 6941 | Q42: =SUM(Q10:Q40) -> 84
A43: MEANS | C43: =AVERAGE(C10:C40) -> 4.9 | E43: =MODE(E10:E40) -> 7 | F43: =AVERAGE(F10:F40) -> 9.9666667 | K43: =AVERAGE(K10:K40) -> 116.3 | L43: =AVERAGE(L10:L40) -> 273.53333 | M43: =AVERAGE(M10:M40) -> 244.53333 | N43: =AVERAGE(N10:N40) -> 284.23333 | O43: =AVERAGE(O10:O40) -> 78.033333 | P43: =AVERAGE(P10:P40) -> 231.36667 | Q43: =AVERAGE(Q10:Q40) -> 2.8 | AN43: =AVERAGE(AN10:AN40) -> -2.5631515 | AO43: =AVERAGE(AO10:AO40) -> -0.91851032 | AP43: =AVERAGE(AP10:AP40) -> -1.8444383

Sheet 2100z
E7: WIND | L7: TEMP AND HUMIDITY | Q7: CLOUDS | U7: CLOUDS REPORTED BY 8NsChshs GROUPS | AH7: REMARKS | AN7: S.rule - Formula | AY7: Formula
A8: DAY | B8: HOUR | C8: Total cloud Amt. | D8: Wind indicator | E8: DIRECTION | F8: SPEED | G8: VISIBILITY | H8: Weather Indicator | I8: PRESENT WEATHER | J8: PAST WEATHER | K8: SEA LEVEL PRESSURE | L8: Dry Bulb | M8: Wet Bulb | N8: Vapour Pressure | O8: Relative humidity | P8: Dew Point | Q8: Total amt. Nh | R8: Form of CL | S8: Form of CM | T8: Form of CH | U8: Lowest layer | X8: 3/8 or more | AB8: 5/8 or more | AE8: Cb cloud | AN8: Vapour Pressure | AO8: Relative humidity | AP8: Dew Point | AY8: Vapour Pressure | AZ8: Relative humidity | BA8: Dew Point
U9: Amount | V9: Form | W9: Height | X9: Indicator | Y9: Amount | Z9: Form | AA9: Height | AB9: Amount | AC9: Form | AD9: Height | AE9: Amount | AF9: Form | AG9: Height | BC9: ####### | BD9: ********* | BE9: &&&&&&
A10: 1 | B10: 17 | C10: 3 | D10: 4 | E10: 8 | F10: 11 | G10: 76 | H10: 2 | K10: 122 | L10: 286 | M10: 254 | N10: 295 | O10: 75 | P10: 238 | Q10: 2 | R10: 8 | S10: 0 | T10: 1 | U10: 1 | V10: 8 | W10: 69 | X10: 8 | AN10: =N10-AY10 -> -7.3040336 | AO10: =O10-AZ10 -> -2.2225215 | AP10: =P10-BA10 -> -4.2051099 | AY10: =10*(BE10-BD10*((L10/10)-(M10/10))*0.00066*(1+(0.00115*(M10/10)))) -> 302.30403 | AZ10: =((AY10/10)*100)/BC10 -> 77.222522 | BA10: =(243.5*LN((AY10/10)/6.112))/(17.67-LN((AY10/10)/6.112))*10 -> 242.20511 | BC10: =6.112*2.718^((17.67*(L10/10))/((L10/10)+243.5)) -> 39.147133 | BD10: 1013.2 | BE10: =6.112*2.718^((17.67*(M10/10))/((M10/10)+243.5)) -> 32.432788
A11: 2 | B11: 17 | C11: 2 | D11: 4 | E11: 10 | F11: 12 | G11: 75 | H11: 2 | K11: 114 | L11: 287 | M11: 249 | N11: 285 | O11: 72 | P11: 232 | Q11: 1 | R11: 2 | S11: 0 | T11: 1 | U11: 1 | V11: 8 | W11: 63 | X11: 8 | AN11: =N11-AY11 -> -3.6652601 | AO11: =O11-AZ11 -> -1.3114655 | AP11: =P11-BA11 -> -2.5368017 | AY11: =10*(BE11-BD11*((L11/10)-(M11/10))*0.00066*(1+(0.00115*(M11/10)))) -> 288.66526 | AZ11: =((AY11/10)*100)/BC11 -> 73.311465 | BA11: =(243.5*LN((AY11/10)/6.112))/(17.67-LN((AY11/10)/6.112))*10 -> 234.5368 | BC11: =6.112*2.718^((17.67*(L11/10))/((L11/10)+243.5)) -> 39.375186 | BD11: 1013.2 | BE11: =6.112*2.718^((17.67*(M11/10))/((M11/10)+243.5)) -> 31.480396
A12: 3 | B12: 17 | C12: 2 | D12: 4 | E12: 10 | F12: 12 | G12: 75 | H12: 2 | K12: 116 | L12: 286 | M12: 250 | N12: 289 | O12: 74 | P12: 234 | Q12: 1 | R12: 2 | S12: 0 | T12: 2 | U12: 1 | V12: 8 | W12: 69 | X12: 8 | AN12: =N12-AY12 -> -2.9231672 | AO12: =O12-AZ12 -> -0.57076503 | AP12: =P12-BA12 -> -2.3969334 | AY12: =10*(BE12-BD12*((L12/10)-(M12/10))*0.00066*(1+(0.00115*(M12/10)))) -> 291.92317 | AZ12: =((AY12/10)*100)/BC12 -> 74.570765 | BA12: =(243.5*LN((AY12/10)/6.112))/(17.67-LN((AY12/10)/6.112))*10 -> 236.39693 | BC12: =6.112*2.718^((17.67*(L12/10))/((L12/10)+243.5)) -> 39.147133 | BD12: 1013.2 | BE12: =6.112*2.718^((17.67*(M12/10))/((M12/10)+243.5)) -> 31.668892
A13: 4 | B13: 17 | C13: 2 | D13: 4 | E13: 8 | F13: 12 | G13: 80 | H13: 2 | K13: 124 | L13: 283 | M13: 257 | N13: 310 | O13: 81 | P13: 246 | Q13: 2 | R13: 2 | S13: 0 | T13: 2 | U13: 2 | V13: 8 | W13: 69 | X13: 8 | AN13: =N13-AY13 -> -2.2620588 | AO13: =O13-AZ13 -> -0.17052641 | AP13: =P13-BA13 -> -1.6148586 | AY13: =10*(BE13-BD13*((L13/10)-(M13/10))*0.00066*(1+(0.00115*(M13/10)))) -> 312.26206 | AZ13: =((AY13/10)*100)/BC13 -> 81.170526 | BA13: =(243.5*LN((AY13/10)/6.112))/(17.67-LN((AY13/10)/6.112))*10 -> 247.61486 | BC13: =6.112*2.718^((17.67*(L13/10))/((L13/10)+243.5)) -> 38.469882 | BD13: 1013.2 | BE13: =6.112*2.718^((17.67*(M13/10))/((M13/10)+243.5)) -> 33.016243
A14: 5 | B14: 17 | C14: 4 | D14: 4 | E14: 9 | F14: 14 | G14: 78 | H14: 2 | K14: 118 | L14: 287 | M14: 255 | N14: 300 | O14: 77 | P14: 241 | Q14: 1 | R14: 1 | S14: 0 | T14: 1 | U14: 1 | V14: 8 | W14: 66 | X14: 8 | Y14: 4 | Z14: 0 | AA14: 900 | AN14: =N14-AY14 -> -4.2363182 | AO14: =O14-AZ14 -> -0.26600121 | AP14: =P14-BA14 -> -2.2669103 | AY14: =10*(BE14-BD14*((L14/10)-(M14/10))*0.00066*(1+(0.00115*(M14/10)))) -> 304.23632 | AZ14: =((AY14/10)*100)/BC14 -> 77.266001 | BA14: =(243.5*LN((AY14/10)/6.112))/(17.67-LN((AY14/10)/6.112))*10 -> 243.26691 | BC14: =6.112*2.718^((17.67*(L14/10))/((L14/10)+243.5)) -> 39.375186 | BD14: 1013.2 | BE14: =6.112*2.718^((17.67*(M14/10))/((M14/10)+243.5)) -> 32.626262
A15: 6 | B15: 17 | C15: 2 | D15: 4 | E15: 11 | F15: 15 | G15: 80 | H15: 2 | K15: 113 | L15: 284 | M15: 249 | N15: 289 | O15: 74 | P15: 234 | Q15: 1 | R15: 1 | S15: 0 | T15: 1 | U15: 1 | V15: 8 | W15: 66 | X15: 8 | AN15: =N15-AY15 -> -1.7288418 | AO15: =O15-AZ15 -> -1.1344366 | AP15: =P15-BA15 -> -1.7171433 | AY15: =10*(BE15-BD15*((L15/10)-(M15/10))*0.00066*(1+(0.00115*(M15/10)))) -> 290.72884 | AZ15: =((AY15/10)*100)/BC15 -> 75.134437 | BA15: =(243.5*LN((AY15/10)/6.112))/(17.67-LN((AY15/10)/6.112))*10 -> 235.71714 | BC15: =6.112*2.718^((17.67*(L15/10))/((L15/10)+243.5)) -> 38.694486 | BD15: 1013.2 | BE15: =6.112*2.718^((17.67*(M15/10))/((M15/10)+243.5)) -> 31.480396
A16: 7 | B16: 17 | C16: 5 | D16: 4 | E16: 11 | F16: 14 | G16: 76 | H16: 2 | K16: 107 | L16: 282 | M16: 252 | N16: 296 | O16: 77 | P16: 239 | Q16: 1 | R16: 1 | S16: 0 | T16: 2 | U16: 1 | V16: 8 | W16: 66 | X16: 8 | Y16: 5 | Z16: 0 | AA16: 840 | AN16: =N16-AY16 -> -3.8457417 | AO16: =O16-AZ16 -> -1.3983852 | AP16: =P16-BA16 -> -1.8456434 | AY16: =10*(BE16-BD16*((L16/10)-(M16/10))*0.00066*(1+(0.00115*(M16/10)))) -> 299.84574 | AZ16: =((AY16/10)*100)/BC16 -> 78.398385 | BA16: =(243.5*LN((AY16/10)/6.112))/(17.67-LN((AY16/10)/6.112))*10 -> 240.84564 | BC16: =6.112*2.718^((17.67*(L16/10))/((L16/10)+243.5)) -> 38.246418 | BD16: 1013.2 | BE16: =6.112*2.718^((17.67*(M16/10))/((M16/10)+243.5)) -> 32.048848
A17: 8 | B17: 17 | C17: 1 | D17: 4 | E17: 10 | F17: 14 | G17: 75 | H17: 2 | K17: 104 | L17: 284 | M17: 254 | N17: 300 | O17: 78 | P17: 241 | Q17: 1 | R17: 2 | S17: 0 | T17: 0 | U17: 1 | V17: 8 | W17: 69 | X17: 8 | AN17: =N17-AY17 -> -3.6805237 | AO17: =O17-AZ17 -> -0.48160138 | AP17: =P17-BA17 -> -1.9621047 | AY17: =10*(BE17-BD17*((L17/10)-(M17/10))*0.00066*(1+(0.00115*(M17/10)))) -> 303.68052 | AZ17: =((AY17/10)*100)/BC17 -> 78.481601 | BA17: =(243.5*LN((AY17/10)/6.112))/(17.67-LN((AY17/10)/6.112))*10 -> 242.9621 | BC17: =6.112*2.718^((17.67*(L17/10))/((L17/10)+243.5)) -> 38.694486 | BD17: 1013.2 | BE17: =6.112*2.718^((17.67*(M17/10))/((M17/10)+243.5)) -> 32.432788
A18: 9 | B18: 17 | C18: 7 | D18: 4 | E18: 9 | F18: 16 | G18: 78 | H18: 2 | K18: 106 | L18: 283 | M18: 250 | N18: 292 | O18: 76 | P18: 236 | Q18: 1 | R18: 2 | S18: 0 | T18: 1 | U18: 1 | V18: 8 | W18: 66 | X18: 8 | Y18: 6 | Z18: 0 | AA18: 900 | AN18: =N18-AY18 -> -1.9869796 | AO18: =O18-AZ18 -> -0.42003637 | AP18: =P18-BA18 -> -1.5659006 | AY18: =10*(BE18-BD18*((L18/10)-(M18/10))*0.00066*(1+(0.00115*(M18/10)))) -> 293.98698 | AZ18: =((AY18/10)*100)/BC18 -> 76.420036 | BA18: =(243.5*LN((AY18/10)/6.112))/(17.67-LN((AY18/10)/6.112))*10 -> 237.5659 | BC18: =6.112*2.718^((17.67*(L18/10))/((L18/10)+243.5)) -> 38.469882 | BD18: 1013.2 | BE18: =6.112*2.718^((17.67*(M18/10))/((M18/10)+243.5)) -> 31.668892
A19: 10 | B19: 17 | C19: 7 | D19: 4 | E19: 10 | F19: 12 | G19: 75 | H19: 2 | K19: 90 | L19: 290 | M19: 253 | N19: 294 | O19: 73 | P19: 237 | Q19: 2 | R19: 4 | S19: 0 | T19: 1 | U19: 2 | V19: 8 | W19: 60 | X19: 8 | Y19: 7 | Z19: 0 | AA19: 900 | AN19: =N19-AY19 -> -2.9409544 | AO19: =O19-AZ19 -> -1.1123559 | AP19: =P19-BA19 -> -2.2266228 | AY19: =10*(BE19-BD19*((L19/10)-(M19/10))*0.00066*(1+(0.00115*(M19/10)))) -> 296.94095 | AZ19: =((AY19/10)*100)/BC19 -> 74.112356 | BA19: =(243.5*LN((AY19/10)/6.112))/(17.67-LN((AY19/10)/6.112))*10 -> 239.22662 | BC19: =6.112*2.718^((17.67*(L19/10))/((L19/10)+243.5)) -> 40.066322 | BD19: 1013.2 | BE19: =6.112*2.718^((17.67*(M19/10))/((M19/10)+243.5)) -> 32.240318
A20: 11 | B20: 17 | C20: 7 | D20: 4 | E20: 11 | F20: 10 | G20: 68 | H20: 1 | I20: 15 | J20: 22 | K20: 89 | L20: 283 | M20: 251 | N20: 294 | O20: 76 | P20: 237 | Q20: 2 | R20: 8 | S20: 0 | T20: 2 | U20: 2 | V20: 8 | W20: 60 | X20: 8 | Y20: 7 | Z20: 0 | AA20: 840 | AH20: jp-nne hz | AN20: =N20-AY20 -> -2.567281 | AO20: =O20-AZ20 -> -1.0907692 | AP20: =P20-BA20 -> -2.0173454 | AY20: =10*(BE20-BD20*((L20/10)-(M20/10))*0.00066*(1+(0.00115*(M20/10)))) -> 296.56728 | AZ20: =((AY20/10)*100)/BC20 -> 77.090769 | BA20: =(243.5*LN((AY20/10)/6.112))/(17.67-LN((AY20/10)/6.112))*10 -> 239.01735 | BC20: =6.112*2.718^((17.67*(L20/10))/((L20/10)+243.5)) -> 38.469882 | BD20: 1013.2 | BE20: =6.112*2.718^((17.67*(M20/10))/((M20/10)+243.5)) -> 31.858374
A21: 12 | B21: 17 | C21: 7 | D21: 4 | E21: 7 | F21: 12 | G21: 78 | H21: 1 | I21: 2 | J21: 82 | K21: 107 | L21: 285 | M21: 240 | N21: 264 | O21: 67 | P21: 219 | Q21: 3 | R21: 8 | S21: 4 | T21: 2 | U21: 1 | V21: 8 | W21: 63 | X21: 8 | Y21: 7 | Z21: 0 | AA21: 840 | AH21: hz | AN21: =N21-AY21 -> -3.3538168 | AO21: =O21-AZ21 -> -1.6927553 | AP21: =P21-BA21 -> -2.8940791 | AY21: =10*(BE21-BD21*((L21/10)-(M21/10))*0.00066*(1+(0.00115*(M21/10)))) -> 267.35382 | AZ21: =((AY21/10)*100)/BC21 -> 68.692755 | BA21: =(243.5*LN((AY21/10)/6.112))/(17.67-LN((AY21/10)/6.112))*10 -> 221.89408 | BC21: =6.112*2.718^((17.67*(L21/10))/((L21/10)+243.5)) -> 38.920235 | BD21: 1013.2 | BE21: =6.112*2.718^((17.67*(M21/10))/((M21/10)+243.5)) -> 29.82764
A22: 13 | B22: 17 | C22: 1 | D22: 4 | E22: 7 | F22: 9 | G22: 80 | H22: 2 | K22: 115 | L22: 297 | M22: 250 | N22: 280 | O22: 67 | P22: 229 | Q22: 1 | R22: 2 | S22: 0 | T22: 1 | U22: 1 | V22: 8 | W22: 63 | X22: 8 | AN22: =N22-AY22 -> -4.355855 | AO22: =O22-AZ22 -> -1.1576425 | AP22: =P22-BA22 -> -3.0478522 | AY22: =10*(BE22-BD22*((L22/10)-(M22/10))*0.00066*(1+(0.00115*(M22/10)))) -> 284.35586 | AZ22: =((AY22/10)*100)/BC22 -> 68.157642 | BA22: =(243.5*LN((AY22/10)/6.112))/(17.67-LN((AY22/10)/6.112))*10 -> 232.04785 | BC22: =6.112*2.718^((17.67*(L22/10))/((L22/10)+243.5)) -> 41.720318 | BD22: 1013.2 | BE22: =6.112*2.718^((17.67*(M22/10))/((M22/10)+243.5)) -> 31.668892
A23: 14 | B23: 17 | C23: 6 | D23: 4 | E23: 9 | F23: 12 | G23: 80 | H23: 2 | K23: 111 | L23: 294 | M23: 245 | N23: 268 | O23: 65 | P23: 222 | Q23: 1 | R23: 2 | S23: 0 | T23: 2 | U23: 1 | V23: 8 | W23: 63 | X23: 8 | Y23: 6 | Z23: 0 | AA23: 840 | AN23: =N23-AY23 -> -5.6718833 | AO23: =O23-AZ23 -> -1.7422326 | AP23: =P23-BA23 -> -3.7316448 | AY23: =10*(BE23-BD23*((L23/10)-(M23/10))*0.00066*(1+(0.00115*(M23/10)))) -> 273.67188 | AZ23: =((AY23/10)*100)/BC23 -> 66.742233 | BA23: =(243.5*LN((AY23/10)/6.112))/(17.67-LN((AY23/10)/6.112))*10 -> 225.73164 | BC23: =6.112*2.718^((17.67*(L23/10))/((L23/10)+243.5)) -> 41.004305 | BD23: 1013.2 | BE23: =6.112*2.718^((17.67*(M23/10))/((M23/10)+243.5)) -> 30.736198
A24: 15 | B24: 17 | C24: 3 | D24: 4 | E24: 11 | F24: 12 | G24: 78 | H24: 2 | K24: 105 | L24: 291 | M24: 239 | N24: 255 | O24: 63 | P24: 214 | Q24: 1 | R24: 2 | S24: 0 | T24: 1 | U24: 1 | V24: 8 | W24: 63 | X24: 8 | AN24: =N24-AY24 -> -5.7590137 | AO24: =O24-AZ24 -> -1.7060056 | AP24: =P24-BA24 -> -3.8026845 | AY24: =10*(BE24-BD24*((L24/10)-(M24/10))*0.00066*(1+(0.00115*(M24/10)))) -> 260.75901 | AZ24: =((AY24/10)*100)/BC24 -> 64.706006 | BA24: =(243.5*LN((AY24/10)/6.112))/(17.67-LN((AY24/10)/6.112))*10 -> 217.80268 | BC24: =6.112*2.718^((17.67*(L24/10))/((L24/10)+243.5)) -> 40.299044 | BD24: 1013.2 | BE24: =6.112*2.718^((17.67*(M24/10))/((M24/10)+243.5)) -> 29.648777
A25: 16 | B25: 17 | C25: 6 | D25: 4 | E25: 8 | F25: 12 | G25: 68 | H25: 1 | I25: 15 | J25: 22 | K25: 120 | L25: 293 | M25: 255 | N25: 296 | O25: 73 | P25: 239 | Q25: 4 | R25: 8 | S25: 0 | T25: 2 | U25: 3 | V25: 8 | W25: 54 | X25: 8 | Y25: 5 | Z25: 0 | AA25: 840 | AH25: jp-ene | AN25: =N25-AY25 -> -4.1063863 | AO25: =O25-AZ25 -> -0.61316935 | AP25: =P25-BA25 -> -1.9902447 | AY25: =10*(BE25-BD25*((L25/10)-(M25/10))*0.00066*(1+(0.00115*(M25/10)))) -> 300.10639 | AZ25: =((AY25/10)*100)/BC25 -> 73.613169 | BA25: =(243.5*LN((AY25/10)/6.112))/(17.67-LN((AY25/10)/6.112))*10 -> 240.99024 | BC25: =6.112*2.718^((17.67*(L25/10))/((L25/10)+243.5)) -> 40.76803 | BD25: 1013.2 | BE25: =6.112*2.718^((17.67*(M25/10))/((M25/10)+243.5)) -> 32.626262
A26: 17 | B26: 17 | C26: 8 | D26: 4 | E26: 8 | F26: 5 | G26: 50 | H26: 1 | I26: 60 | J26: 82 | K26: 139 | L26: 240 | M26: 235 | N26: 286 | O26: 96 | P26: 233 | Q26: 8 | R26: 8 | S26: / | T26: / | U26: 4 | V26: 8 | W26: 36 | X26: 8 | Y26: 6 | Z26: 6 | AA26: 105 | AH26: pro @ 16:05-> | AN26: =N26-AY26 -> 0.0070628893 | AO26: =O26-AZ26 -> 0.11814684 | AP26: =P26-BA26 -> 0.0027640451 | AY26: =10*(BE26-BD26*((L26/10)-(M26/10))*0.00066*(1+(0.00115*(M26/10)))) -> 285.99294 | AZ26: =((AY26/10)*100)/BC26 -> 95.881853 | BA26: =(243.5*LN((AY26/10)/6.112))/(17.67-LN((AY26/10)/6.112))*10 -> 232.99724 | BC26: =6.112*2.718^((17.67*(L26/10))/((L26/10)+243.5)) -> 29.82764 | BD26: 1013.2 | BE26: =6.112*2.718^((17.67*(M26/10))/((M26/10)+243.5)) -> 28.942686
